
<robot name="qtrobot">
  <link name="head_sphere"/>
    <visual>
      <origin xyz="0 6 0" rpy="0 0 0"/>
      <geometry>
        <sphere radius="10"/>
      </geometry>
    </visual>
  </link>

  <link name="head_box"/>
    <visual>
      <origin xyz="0 7 0" rpy="0 0 0"/>
      <geometry>
        <box size="20 12 12"/>
      </geometry>
    </visual>
  </link>

  <link name="neck"/>
    <visual>
      <origin xyz="0 21 0" rpy="0 0 0"/>
      <geometry>
        <cylinder length="2" radius="1"/>
      </geometry>
    </visual>
  </link>

  <link name="body_cylinder"/>
    <visual>
      <origin xyz="0 20 0" rpy="0 0 0"/>
      <geometry>
        <cylinder length="40" radius="10"/>
      </geometry>
    </visual>
  </link>

  <link name="right_shoulder"/>
    <visual>
      <origin xyz="-12 14 0" rpy="0 0 0"/>
      <geometry>
        <cylinder length="12" radius="2"/>
      </geometry>
    </visual>
  </link>
  
  <link name="right_arm"/>
    <visual>
      <origin xyz="0 -10 0" rpy="0 0 0"/>
      <geometry>
        <cylinder length="8" radius="2"/>
      </geometry>
    </visual>
  </link>

  <link name="right_hand"/>
    <visual>
      <origin xyz="0 -4 0" rpy="0 0 0"/>
      <geometry>
        <sphere radius="2"/>
      </geometry>
    </visual>
  </link>

  <link name="left_shoulder"/>
    <visual>
      <origin xyz="12 14 0" rpy="0 0 0"/>
      <geometry>
        <cylinder length="12" radius="2"/>
      </geometry>
    </visual>
  </link>

  <link name="left_arm"/>
    <visual>
      <origin xyz="0 -10 0" rpy="0 0 0"/>
      <geometry>
        <cylinder length="8" radius="2"/>
      </geometry>
    </visual>
  </link>

  <link name="left_hand"/>
    <visual>
      <origin xyz="0 -4 0" rpy="0 0 0"/>
      <geometry>
        <sphere radius="2"/>
      </geometry>
    </visual>
  </link>

  <joint name="head" type="fixed">
    <parent link="head_box"/>
    <child link="head_sphere"/>
    <origin xyz="0 6 0"/>
  </joint>

  <joint name="hn_pitch" type="revolute">
    <parent link="neck"/>
    <child link="head_box"/>
    <origin xyz="0 7 0"/>
    <axis xyz="1 0 0"/>
    <limit effort="1000.0" lower="-0.262" upper="0.349" velocity="0.5"/>
  </joint>

  <joint name="hd_yaw" type="revolute">
    <parent link="neck"/>
    <child link="head_box"/>
    <origin xyz="0 7 0"/>
    <axis xyz="0 1 0"/>
    <limit effort="1000.0" lower="-0.785" upper="0.785" velocity="0.5"/>
  </joint>

  <joint name="neck_body" type="fixed">
    <parent link="body_cylinder"/>
    <child link="neck"/>
    <origin xyz="0 21 0"/>
  </joint>

  <joint name="right_shoulder_roll" type="revolute">
    <parent link="body_cylinder"/>
    <child link="right_shoulder"/>
    <origin xyz="-12 14 0"/>
    <axis xyz="0 0 -1"/>
    <limit effort="1000.0" lower="-1.571" upper="0.0" velocity="0.5"/>
  </joint>

  <joint name="right_shoulder_pitch" type="revolute">
    <parent link="body_cylinder"/>
    <child link="right_shoulder"/>
    <origin xyz="-12 14 0"/>
    <axis xyz="-1 0 0"/>
    <limit effort="1000.0" lower="-2.356" upper="2.356" velocity="0.5"/>
  </joint>

  <joint name="right_elbow_roll" type="revolute">
    <parent link="right_shoulder"/>
    <child link="right_arm"/>
    <origin xyz="0 -10 0"/>
    <axis xyz="0 0 -1"/>
    <limit effort="1000.0" lower="-1.571" upper="0.0" velocity="0.5"/>
  </joint>

  <joint name="right_eh" type="fixed">
    <parent link="right_arm"/>
    <child link="right_hand"/>
  </joint>

  <joint name="left_shoulder_roll" type="revolute">
    <parent link="body_cylinder"/>
    <child link="left_shoulder"/>
    <origin xyz="-12 14 0"/>
    <axis xyz="0 0 1"/>
    <limit effort="1000.0" lower="-1.571" upper="0.0" velocity="0.5"/>
  </joint>

  <joint name="left_shoulder_pitch" type="revolute">
    <parent link="body_cylinder"/>
    <child link="left_shoulder"/>
    <origin xyz="-12 14 0"/>
    <axis xyz="1 0 0"/>
    <limit effort="1000.0" lower="-2.356" upper="2.356" velocity="0.5"/>
  </joint>

  <joint name="left_elbow_roll" type="revolute">
    <parent link="left_shoulder"/>
    <child link="left_arm"/>
    <origin xyz="0 -10 0"/>
    <axis xyz="0 0 1"/>
    <limit effort="1000.0" lower="-1.571" upper="0.0" velocity="0.5"/>
  </joint>

  <joint name="left_eh" type="fixed">
    <parent link="left_arm"/>
    <child link="left_hand"/>
  </joint>

</robot>

